> /Users/athmajanvivekananthan/WCE/JEPA - MARL/multi-agent/PPO/bert_marl/mode20-dqn/classify.py(81)<module>()
     80
---> 81         for data in data_loader:
     82             # TODO optimize
23.6
tensor([3, 3, 3,  ..., 3, 3, 3])
*** AttributeError: 'Tensor' object has no attribute 'to_array'
*** AttributeError: 'Tensor' object has no attribute 'to_np_array'
array([3, 3, 3, ..., 3, 3, 3])
Traceback (most recent call last):
  File "/Users/athmajanvivekananthan/WCE/JEPA - MARL/multi-agent/PPO/bert_marl/mode20-dqn/classify.py", line 81, in <module>
    for data in data_loader:
  File "/Users/athmajanvivekananthan/miniconda3/lib/python3.11/bdb.py", line 90, in trace_dispatch
    return self.dispatch_line(frame)
           ^^^^^^^^^^^^^^^^^^^^^^^^^
  File "/Users/athmajanvivekananthan/miniconda3/lib/python3.11/bdb.py", line 115, in dispatch_line
    if self.quitting: raise BdbQuit
                      ^^^^^^^^^^^^^
bdb.BdbQuit
If you suspect this is an IPython 8.26.0 bug, please report it at:
    https://github.com/ipython/ipython/issues
or send an email to the mailing list at ipython-dev@python.org
You can print a more detailed traceback right now with "%tb", or use "%debug"
to interactively debug it.
Extra-detailed tracebacks for bug-reporting purposes can be enabled via:
    %config Application.verbose_crash=True